[32mINFO    [0m juju.model:__init__.py:2301 Deploying local:postgresql-k8s-3
[32mINFO    [0m juju.model:__init__.py:3254 Waiting for model:
  test-storage-postgresql-k8s/0 [idle] waiting: agent initialising
[32mINFO    [0m juju.model:__init__.py:3254 Waiting for model:
  test-storage-postgresql-k8s/0 [idle] waiting: awaiting for cluster to start
[32mINFO    [0m juju.model:__init__.py:3254 Waiting for model:
  test-storage-postgresql-k8s/0 [executing] active: Primary
[32mINFO    [0m juju.model:__init__.py:3254 Waiting for model:
  test-storage-postgresql-k8s/0 [idle] active: Primary
[32mINFO    [0m pytest_operator.plugin:plugin.py:937 Model status:

Model    Controller          Cloud/Region        Version  SLA          Timestamp
testing  concierge-microk8s  microk8s/localhost  3.6.6    unsupported  02:23:28Z

App                          Version  Status   Scale  Charm           Channel  Rev  Address         Exposed  Message
postgresql-k8s                        waiting    0/3  postgresql-k8s             2  10.152.183.167  no       installing agent
test-storage-postgresql-k8s  14.17    active       1  postgresql-k8s             3  10.152.183.102  no       

Unit                            Workload  Agent       Address       Ports  Message
postgresql-k8s/0                waiting   allocating                       installing agent
postgresql-k8s/1                waiting   allocating                       installing agent
postgresql-k8s/2                waiting   allocating                       installing agent
test-storage-postgresql-k8s/0*  active    idle        10.1.204.224         Primary

[32mINFO    [0m pytest_operator.plugin:plugin.py:943 Juju error logs:

unit-postgresql-k8s-1: 01:33:25 ERROR unit.postgresql-k8s/1.juju-log pgdata folder not found in /var/lib/postgresql/data/pgdata
unit-postgresql-k8s-2: 01:37:17 ERROR unit.postgresql-k8s/2.juju-log Cluster upgrade failed, ensure pre-upgrade checks are ran first.
unit-postgresql-k8s-0: 01:47:01 ERROR juju.worker.dependency "log-sender" manifold worker returned unexpected error: sending log message: websocket: close 1005 (no status): websocket: close sent
unit-postgresql-k8s-1: 01:47:01 ERROR juju.worker.dependency "log-sender" manifold worker returned unexpected error: sending log message: websocket: close 1005 (no status): websocket: close sent
unit-postgresql-k8s-0: 01:51:23 ERROR unit.postgresql-k8s/0.juju-log Cluster upgrade failed, ensure pre-upgrade checks are ran first.
unit-postgresql-k8s-1: 02:04:36 ERROR unit.postgresql-k8s/1.juju-log Uncaught exception while in charm code:
Traceback (most recent call last):
  File "/var/lib/juju/agents/unit-postgresql-k8s-1/charm/venv/lib/python3.10/site-packages/ops/model.py", line 3407, in _run
    result = subprocess.run(args, **kwargs)  # type: ignore
  File "/usr/lib/python3.10/subprocess.py", line 526, in run
    raise CalledProcessError(retcode, process.args,
subprocess.CalledProcessError: Command '('/var/lib/juju/tools/unit-postgresql-k8s-1/relation-get', '-r', '3', '-', 'postgresql-k8s/1', '--format=json')' returned non-zero exit status 1.

The above exception was the direct cause of the following exception:

Traceback (most recent call last):
  File "/var/lib/juju/agents/unit-postgresql-k8s-1/charm/src/charm.py", line 2520, in <module>
    main(PostgresqlOperatorCharm, use_juju_for_storage=True)
  File "/var/lib/juju/agents/unit-postgresql-k8s-1/charm/venv/lib/python3.10/site-packages/ops/__init__.py", line 347, in __call__
    return _main.main(charm_class=charm_class, use_juju_for_storage=use_juju_for_storage)
  File "/var/lib/juju/agents/unit-postgresql-k8s-1/charm/venv/lib/python3.10/site-packages/ops/_main.py", line 565, in main
    manager.run()
  File "/var/lib/juju/agents/unit-postgresql-k8s-1/charm/venv/lib/python3.10/site-packages/ops/_main.py", line 550, in run
    self._emit()
  File "/var/lib/juju/agents/unit-postgresql-k8s-1/charm/venv/lib/python3.10/site-packages/ops/_main.py", line 502, in _emit
    self._emit_charm_event(self.dispatcher.event_name)
  File "/var/lib/juju/agents/unit-postgresql-k8s-1/charm/venv/lib/python3.10/site-packages/ops/_main.py", line 537, in _emit_charm_event
    event_to_emit.emit(*args, **kwargs)
  File "/var/lib/juju/agents/unit-postgresql-k8s-1/charm/venv/lib/python3.10/site-packages/ops/framework.py", line 348, in emit
    framework._emit(event)
  File "/var/lib/juju/agents/unit-postgresql-k8s-1/charm/venv/lib/python3.10/site-packages/ops/framework.py", line 907, in _emit
    self._reemit(event_path)
  File "/var/lib/juju/agents/unit-postgresql-k8s-1/charm/venv/lib/python3.10/site-packages/ops/framework.py", line 997, in _reemit
    custom_handler(event)
  File "/var/lib/juju/agents/unit-postgresql-k8s-1/charm/lib/charms/tempo_coordinator_k8s/v0/charm_tracing.py", line 1109, in wrapped_function
    return callable(*args, **kwargs)  # type: ignore
  File "/var/lib/juju/agents/unit-postgresql-k8s-1/charm/src/charm.py", line 1525, in _on_update_status
    if not self._on_update_status_early_exit_checks(container):
  File "/var/lib/juju/agents/unit-postgresql-k8s-1/charm/lib/charms/tempo_coordinator_k8s/v0/charm_tracing.py", line 1109, in wrapped_function
    return callable(*args, **kwargs)  # type: ignore
  File "/var/lib/juju/agents/unit-postgresql-k8s-1/charm/src/charm.py", line 1480, in _on_update_status_early_exit_checks
    if not self.upgrade.idle:
  File "/var/lib/juju/agents/unit-postgresql-k8s-1/charm/lib/charms/data_platform_libs/v0/upgrade.py", line 663, in idle
    return set(self.unit_states) == {"idle"}
  File "/var/lib/juju/agents/unit-postgresql-k8s-1/charm/lib/charms/data_platform_libs/v0/upgrade.py", line 634, in unit_states
    return [self.peer_relation.data[unit].get("state", "") for unit in self.app_units]
  File "/var/lib/juju/agents/unit-postgresql-k8s-1/charm/lib/charms/data_platform_libs/v0/upgrade.py", line 634, in <listcomp>
    return [self.peer_relation.data[unit].get("state", "") for unit in self.app_units]
  File "/usr/lib/python3.10/_collections_abc.py", line 824, in get
    return self[key]
  File "/var/lib/juju/agents/unit-postgresql-k8s-1/charm/venv/lib/python3.10/site-packages/ops/model.py", line 1966, in __getitem__
    return super().__getitem__(key)
  File "/var/lib/juju/agents/unit-postgresql-k8s-1/charm/venv/lib/python3.10/site-packages/ops/model.py", line 892, in __getitem__
    return self._data[key]
  File "/var/lib/juju/agents/unit-postgresql-k8s-1/charm/venv/lib/python3.10/site-packages/ops/model.py", line 876, in _data
    data = self._lazy_data = self._load()
  File "/var/lib/juju/agents/unit-postgresql-k8s-1/charm/venv/lib/python3.10/site-packages/ops/model.py", line 1846, in _load
    return self._backend.relation_get(self.relation.id, self._entity.name, self._is_app)
  File "/var/lib/juju/agents/unit-postgresql-k8s-1/charm/venv/lib/python3.10/site-packages/ops/model.py", line 3486, in relation_get
    raw_data_content = self._run(*args, return_output=True, use_json=True)
  File "/var/lib/juju/agents/unit-postgresql-k8s-1/charm/venv/lib/python3.10/site-packages/ops/model.py", line 3409, in _run
    raise ModelError(e.stderr) from e
ops.model.ModelError: ERROR permission denied

unit-postgresql-k8s-0: 02:04:36 ERROR unit.postgresql-k8s/0.juju-log Uncaught exception while in charm code:
Traceback (most recent call last):
  File "/var/lib/juju/agents/unit-postgresql-k8s-0/charm/venv/lib/python3.10/site-packages/ops/model.py", line 3407, in _run
    result = subprocess.run(args, **kwargs)  # type: ignore
  File "/usr/lib/python3.10/subprocess.py", line 526, in run
    raise CalledProcessError(retcode, process.args,
subprocess.CalledProcessError: Command '('/var/lib/juju/tools/unit-postgresql-k8s-0/relation-get', '-r', '4', '-', 'postgresql-k8s', '--app', '--format=json')' returned non-zero exit status 1.

The above exception was the direct cause of the following exception:

Traceback (most recent call last):
  File "/var/lib/juju/agents/unit-postgresql-k8s-0/charm/src/charm.py", line 2520, in <module>
    main(PostgresqlOperatorCharm, use_juju_for_storage=True)
  File "/var/lib/juju/agents/unit-postgresql-k8s-0/charm/venv/lib/python3.10/site-packages/ops/__init__.py", line 347, in __call__
    return _main.main(charm_class=charm_class, use_juju_for_storage=use_juju_for_storage)
  File "/var/lib/juju/agents/unit-postgresql-k8s-0/charm/venv/lib/python3.10/site-packages/ops/_main.py", line 563, in main
    manager = _Manager(charm_class, use_juju_for_storage=use_juju_for_storage)
  File "/var/lib/juju/agents/unit-postgresql-k8s-0/charm/venv/lib/python3.10/site-packages/ops/_main.py", line 405, in __init__
    self.charm = self._make_charm(self.framework, self.dispatcher)
  File "/var/lib/juju/agents/unit-postgresql-k8s-0/charm/venv/lib/python3.10/site-packages/ops/_main.py", line 411, in _make_charm
    charm = self._charm_class(framework)
  File "/var/lib/juju/agents/unit-postgresql-k8s-0/charm/lib/charms/tempo_coordinator_k8s/v0/charm_tracing.py", line 732, in wrap_init
    original_init(self, framework, *args, **kwargs)
  File "/var/lib/juju/agents/unit-postgresql-k8s-0/charm/src/charm.py", line 261, in __init__
    self._observer.start_authorisation_rules_observer()
  File "/var/lib/juju/agents/unit-postgresql-k8s-0/charm/src/authorisation_rules_observer.py", line 59, in start_authorisation_rules_observer
    or not self._charm.is_cluster_initialised
  File "/var/lib/juju/agents/unit-postgresql-k8s-0/charm/src/charm.py", line 422, in is_cluster_initialised
    return "cluster_initialised" in self.app_peer_data
  File "/var/lib/juju/agents/unit-postgresql-k8s-0/charm/venv/lib/python3.10/site-packages/ops/model.py", line 883, in __contains__
    return key in self._data
  File "/var/lib/juju/agents/unit-postgresql-k8s-0/charm/venv/lib/python3.10/site-packages/ops/model.py", line 876, in _data
    data = self._lazy_data = self._load()
  File "/var/lib/juju/agents/unit-postgresql-k8s-0/charm/venv/lib/python3.10/site-packages/ops/model.py", line 1846, in _load
    return self._backend.relation_get(self.relation.id, self._entity.name, self._is_app)
  File "/var/lib/juju/agents/unit-postgresql-k8s-0/charm/venv/lib/python3.10/site-packages/ops/model.py", line 3486, in relation_get
    raw_data_content = self._run(*args, return_output=True, use_json=True)
  File "/var/lib/juju/agents/unit-postgresql-k8s-0/charm/venv/lib/python3.10/site-packages/ops/model.py", line 3409, in _run
    raise ModelError(e.stderr) from e
ops.model.ModelError: ERROR permission denied (unauthorized access)

unit-test-storage-postgresql-k8s-0: 02:22:27 ERROR unit.test-storage-postgresql-k8s/0.juju-log failed to change plugins: 
Traceback (most recent call last):
  File "/var/lib/juju/agents/unit-test-storage-postgresql-k8s-0/charm/lib/charms/postgresql_k8s/v0/postgresql.py", line 437, in enable_disable_extensions
    with self._connect_to_database() as connection, connection.cursor() as cursor:
  File "/var/lib/juju/agents/unit-test-storage-postgresql-k8s-0/charm/lib/charms/tempo_coordinator_k8s/v0/charm_tracing.py", line 1109, in wrapped_function
    return callable(*args, **kwargs)  # type: ignore
  File "/var/lib/juju/agents/unit-test-storage-postgresql-k8s-0/charm/lib/charms/postgresql_k8s/v0/postgresql.py", line 184, in _connect_to_database
    connection = psycopg2.connect(
  File "/var/lib/juju/agents/unit-test-storage-postgresql-k8s-0/charm/venv/lib/python3.10/site-packages/psycopg2/__init__.py", line 122, in connect
    conn = _connect(dsn, connection_factory=connection_factory, **kwasync)
psycopg2.OperationalError: connection to server at "test-storage-postgresql-k8s-primary.testing.svc.cluster.local" (10.152.183.82), port 5432 failed: Connection refused
	Is the server running on that host and accepting TCP/IP connections?


The above exception was the direct cause of the following exception:

Traceback (most recent call last):
  File "/var/lib/juju/agents/unit-test-storage-postgresql-k8s-0/charm/src/charm.py", line 797, in _handle_enable_disable_extensions
    self.postgresql.enable_disable_extensions(extensions, database)
  File "/var/lib/juju/agents/unit-test-storage-postgresql-k8s-0/charm/lib/charms/tempo_coordinator_k8s/v0/charm_tracing.py", line 1109, in wrapped_function
    return callable(*args, **kwargs)  # type: ignore
  File "/var/lib/juju/agents/unit-test-storage-postgresql-k8s-0/charm/lib/charms/postgresql_k8s/v0/postgresql.py", line 466, in enable_disable_extensions
    raise PostgreSQLEnableDisableExtensionError() from e
charms.postgresql_k8s.v0.postgresql.PostgreSQLEnableDisableExtensionError
unit-test-storage-postgresql-k8s-0: 02:22:40 ERROR unit.test-storage-postgresql-k8s/0.juju-log failed to change plugins: 
Traceback (most recent call last):
  File "/var/lib/juju/agents/unit-test-storage-postgresql-k8s-0/charm/lib/charms/postgresql_k8s/v0/postgresql.py", line 437, in enable_disable_extensions
    with self._connect_to_database() as connection, connection.cursor() as cursor:
  File "/var/lib/juju/agents/unit-test-storage-postgresql-k8s-0/charm/lib/charms/tempo_coordinator_k8s/v0/charm_tracing.py", line 1109, in wrapped_function
    return callable(*args, **kwargs)  # type: ignore
  File "/var/lib/juju/agents/unit-test-storage-postgresql-k8s-0/charm/lib/charms/postgresql_k8s/v0/postgresql.py", line 184, in _connect_to_database
    connection = psycopg2.connect(
  File "/var/lib/juju/agents/unit-test-storage-postgresql-k8s-0/charm/venv/lib/python3.10/site-packages/psycopg2/__init__.py", line 122, in connect
    conn = _connect(dsn, connection_factory=connection_factory, **kwasync)
psycopg2.OperationalError: connection to server at "test-storage-postgresql-k8s-primary.testing.svc.cluster.local" (10.152.183.82), port 5432 failed: Connection refused
	Is the server running on that host and accepting TCP/IP connections?


The above exception was the direct cause of the following exception:

Traceback (most recent call last):
  File "/var/lib/juju/agents/unit-test-storage-postgresql-k8s-0/charm/src/charm.py", line 797, in _handle_enable_disable_extensions
    self.postgresql.enable_disable_extensions(extensions, database)
  File "/var/lib/juju/agents/unit-test-storage-postgresql-k8s-0/charm/lib/charms/tempo_coordinator_k8s/v0/charm_tracing.py", line 1109, in wrapped_function
    return callable(*args, **kwargs)  # type: ignore
  File "/var/lib/juju/agents/unit-test-storage-postgresql-k8s-0/charm/lib/charms/postgresql_k8s/v0/postgresql.py", line 466, in enable_disable_extensions
    raise PostgreSQLEnableDisableExtensionError() from e
charms.postgresql_k8s.v0.postgresql.PostgreSQLEnableDisableExtensionError

[32mINFO    [0m pytest_operator.plugin:plugin.py:1025 Forgetting model main...