[32mINFO    [0m juju.model:__init__.py:2301 Deploying local:postgresql-k8s-0
[33mWARNING [0m juju.client.connection:connection.py:493 Receiver: Connection closed, reconnecting
[1m[31mERROR   [0m asyncio:base_events.py:1821 Task exception was never retrieved
future: <Task finished name='Task-269' coro=<Connection.reconnect() done, defined at /home/runner/work/postgresql-k8s-operator/postgresql-k8s-operator/.tox/integration/lib/python3.12/site-packages/juju/client/connection.py:700> exception=OSError(9, 'Bad file descriptor')>
Traceback (most recent call last):
  File "/home/runner/work/postgresql-k8s-operator/postgresql-k8s-operator/.tox/integration/lib/python3.12/site-packages/juju/client/connection.py", line 712, in reconnect
    res = await connector(
          ^^^^^^^^^^^^^^^^
  File "/home/runner/work/postgresql-k8s-operator/postgresql-k8s-operator/.tox/integration/lib/python3.12/site-packages/juju/client/connection.py", line 803, in _connect_with_login
    await self._connect(endpoints)
  File "/home/runner/work/postgresql-k8s-operator/postgresql-k8s-operator/.tox/integration/lib/python3.12/site-packages/juju/client/connection.py", line 746, in _connect
    result = await task
             ^^^^^^^^^^
  File "/usr/lib/python3.12/asyncio/tasks.py", line 631, in _wait_for_one
    return f.result()  # May raise f.exception().
           ^^^^^^^^^^
  File "/home/runner/work/postgresql-k8s-operator/postgresql-k8s-operator/.tox/integration/lib/python3.12/site-packages/juju/client/connection.py", line 732, in _try_endpoint
    return await self._open(endpoint, cacert)
           ^^^^^^^^^^^^^^^^^^^^^^^^^^^^^^^^^^
  File "/home/runner/work/postgresql-k8s-operator/postgresql-k8s-operator/.tox/integration/lib/python3.12/site-packages/juju/client/connection.py", line 333, in _open
    await websockets.connect(
  File "/home/runner/work/postgresql-k8s-operator/postgresql-k8s-operator/.tox/integration/lib/python3.12/site-packages/websockets/legacy/client.py", line 654, in __await_impl__
    _transport, protocol = await self._create_connection()
                           ^^^^^^^^^^^^^^^^^^^^^^^^^^^^^^^
  File "/usr/lib/python3.12/asyncio/base_events.py", line 1149, in create_connection
    transport, protocol = await self._create_connection_transport(
                          ^^^^^^^^^^^^^^^^^^^^^^^^^^^^^^^^^^^^^^^^
  File "/usr/lib/python3.12/asyncio/base_events.py", line 1167, in _create_connection_transport
    sock.setblocking(False)
OSError: [Errno 9] Bad file descriptor