[32mINFO    [0m integration.test_backups:test_backups.py:378 Getting original backup config
[32mINFO    [0m integration.test_backups:test_backups.py:385 Deleting the pod
[32mINFO    [0m httpx:_client.py:1038 HTTP Request: DELETE https://10.1.0.140:16443/api/v1/namespaces/test/pods/new-postgresql-k8s-0 "HTTP/1.1 200 OK"
[32mINFO    [0m juju.model:model.py:2972 Waiting for model:
  new-postgresql-k8s/0 [idle] active: Primary
[32mINFO    [0m juju.model:model.py:2972 Waiting for model:
  new-postgresql-k8s/0 [executing] waiting: awaiting for cluster to start
[32mINFO    [0m juju.model:model.py:2972 Waiting for model:
  new-postgresql-k8s/0 [idle] waiting: awaiting for cluster to start
[32mINFO    [0m integration.test_backups:test_backups.py:82 deleting the previously created backups
[32mINFO    [0m pytest_operator.plugin:plugin.py:903 Model status:

Model  Controller          Cloud/Region        Version  SLA          Timestamp
test   microk8s-localhost  microk8s/localhost  3.4.6    unsupported  01:58:33Z

App                 Version  Status  Scale  Charm           Channel        Rev  Address         Exposed  Message
new-postgresql-k8s  14.13    active      1  postgresql-k8s                   2  10.152.183.174  no       
s3-integrator                active      1  s3-integrator   latest/stable   77  10.152.183.217  no       

Unit                   Workload  Agent  Address      Ports  Message
new-postgresql-k8s/0*  active    idle   10.1.94.146         Primary
s3-integrator/0*       active    idle   10.1.94.136         

[32mINFO    [0m pytest_operator.plugin:plugin.py:909 Juju error logs:

unit-postgresql-k8s-gcp-0: 01:30:58 ERROR unit.postgresql-k8s-gcp/0.juju-log Uncaught exception while in charm code:
Traceback (most recent call last):
  File "/var/lib/juju/agents/unit-postgresql-k8s-gcp-0/charm/venv/ops/model.py", line 3319, in _run
    result = subprocess.run(args, **kwargs)  # type: ignore
  File "/usr/lib/python3.10/subprocess.py", line 526, in run
    raise CalledProcessError(retcode, process.args,
subprocess.CalledProcessError: Command '('/var/lib/juju/tools/unit-postgresql-k8s-gcp-0/secret-get', '--label', 'database-peers.postgresql-k8s-gcp.app', '--format=json')' returned non-zero exit status 1.

The above exception was the direct cause of the following exception:

Traceback (most recent call last):
  File "/var/lib/juju/agents/unit-postgresql-k8s-gcp-0/charm/./src/charm.py", line 2247, in <module>
    main(PostgresqlOperatorCharm, use_juju_for_storage=True)
  File "/var/lib/juju/agents/unit-postgresql-k8s-gcp-0/charm/venv/ops/__init__.py", line 343, in __call__
    return _main.main(charm_class=charm_class, use_juju_for_storage=use_juju_for_storage)
  File "/var/lib/juju/agents/unit-postgresql-k8s-gcp-0/charm/venv/ops/_main.py", line 543, in main
    manager.run()
  File "/var/lib/juju/agents/unit-postgresql-k8s-gcp-0/charm/venv/ops/_main.py", line 529, in run
    self._emit()
  File "/var/lib/juju/agents/unit-postgresql-k8s-gcp-0/charm/venv/ops/_main.py", line 518, in _emit
    _emit_charm_event(self.charm, self.dispatcher.event_name, self._juju_context)
  File "/var/lib/juju/agents/unit-postgresql-k8s-gcp-0/charm/venv/ops/_main.py", line 134, in _emit_charm_event
    event_to_emit.emit(*args, **kwargs)
  File "/var/lib/juju/agents/unit-postgresql-k8s-gcp-0/charm/venv/ops/framework.py", line 347, in emit
    framework._emit(event)
  File "/var/lib/juju/agents/unit-postgresql-k8s-gcp-0/charm/venv/ops/framework.py", line 857, in _emit
    self._reemit(event_path)
  File "/var/lib/juju/agents/unit-postgresql-k8s-gcp-0/charm/venv/ops/framework.py", line 947, in _reemit
    custom_handler(event)
  File "/var/lib/juju/agents/unit-postgresql-k8s-gcp-0/charm/lib/charms/tempo_coordinator_k8s/v0/charm_tracing.py", line 1064, in wrapped_function
    return callable(*args, **kwargs)  # type: ignore
  File "/var/lib/juju/agents/unit-postgresql-k8s-gcp-0/charm/./src/charm.py", line 932, in _on_postgresql_pebble_ready
    self.unit.set_workload_version(self._patroni.rock_postgresql_version)
  File "/var/lib/juju/agents/unit-postgresql-k8s-gcp-0/charm/./src/charm.py", line 1566, in _patroni
    self.get_secret(APP_SCOPE, USER_PASSWORD_KEY),
  File "/var/lib/juju/agents/unit-postgresql-k8s-gcp-0/charm/lib/charms/tempo_coordinator_k8s/v0/charm_tracing.py", line 1064, in wrapped_function
    return callable(*args, **kwargs)  # type: ignore
  File "/var/lib/juju/agents/unit-postgresql-k8s-gcp-0/charm/./src/charm.py", line 349, in get_secret
    return self.peer_relation_data(scope).get_secret(peers.id, secret_key)
  File "/var/lib/juju/agents/unit-postgresql-k8s-gcp-0/charm/lib/charms/data_platform_libs/v0/data_interfaces.py", line 521, in wrapper
    return f(self, *args, **kwargs)
  File "/var/lib/juju/agents/unit-postgresql-k8s-gcp-0/charm/lib/charms/data_platform_libs/v0/data_interfaces.py", line 2043, in get_secret
    and full_field not in self.current_secret_fields
  File "/var/lib/juju/agents/unit-postgresql-k8s-gcp-0/charm/lib/charms/data_platform_libs/v0/data_interfaces.py", line 2000, in current_secret_fields
    if content := self._get_group_secret_contents(relation, group):
  File "/var/lib/juju/agents/unit-postgresql-k8s-gcp-0/charm/lib/charms/data_platform_libs/v0/data_interfaces.py", line 2331, in _get_group_secret_contents
    result = super()._get_group_secret_contents(relation, group, secret_fields)
  File "/var/lib/juju/agents/unit-postgresql-k8s-gcp-0/charm/lib/charms/data_platform_libs/v0/data_interfaces.py", line 1123, in _get_group_secret_contents
    if (secret := self._get_relation_secret(relation.id, group)) and (
  File "/var/lib/juju/agents/unit-postgresql-k8s-gcp-0/charm/lib/charms/data_platform_libs/v0/data_interfaces.py", line 508, in wrapper
    return f(self, *args, **kwargs)
  File "/var/lib/juju/agents/unit-postgresql-k8s-gcp-0/charm/lib/charms/data_platform_libs/v0/data_interfaces.py", line 2318, in _get_relation_secret
    return self.secrets.get(
  File "/var/lib/juju/agents/unit-postgresql-k8s-gcp-0/charm/lib/charms/data_platform_libs/v0/data_interfaces.py", line 812, in get
    if secret.meta:
  File "/var/lib/juju/agents/unit-postgresql-k8s-gcp-0/charm/lib/charms/data_platform_libs/v0/data_interfaces.py", line 642, in meta
    self._secret_meta = self._model.get_secret(label=self.label)
  File "/var/lib/juju/agents/unit-postgresql-k8s-gcp-0/charm/venv/ops/model.py", line 307, in get_secret
    content = self._backend.secret_get(id=id, label=label)
  File "/var/lib/juju/agents/unit-postgresql-k8s-gcp-0/charm/venv/ops/model.py", line 3691, in secret_get
    result = self._run('secret-get', *args, return_output=True, use_json=True)
  File "/var/lib/juju/agents/unit-postgresql-k8s-gcp-0/charm/venv/ops/model.py", line 3321, in _run
    raise ModelError(e.stderr) from e
ops.model.ModelError: ERROR permission denied

unit-postgresql-k8s-gcp-0: 01:30:59 ERROR juju.worker.uniter.operation hook "postgresql-pebble-ready" (via hook dispatching script: dispatch) failed: exit status 1
unit-postgresql-k8s-gcp-0: 01:30:59 ERROR juju.worker.uniter pebble poll failed for container "postgresql": failed to send pebble-ready event: hook failed
unit-postgresql-k8s-gcp-0: 01:43:54 ERROR unit.postgresql-k8s-gcp/0.juju-log Kubernetes service get failed: services "postgresql-k8s-gcp" not found
unit-postgresql-k8s-gcp-0: 01:43:54 ERROR unit.postgresql-k8s-gcp/0.juju-log Kubernetes service patch failed: services "postgresql-k8s-gcp" not found
unit-postgresql-k8s-gcp-0: 01:44:03 ERROR unit.postgresql-k8s-gcp/0.juju-log Kubernetes service get failed: services "postgresql-k8s-gcp" not found
unit-postgresql-k8s-gcp-0: 01:44:03 ERROR unit.postgresql-k8s-gcp/0.juju-log Kubernetes service patch failed: services "postgresql-k8s-gcp" not found
unit-postgresql-k8s-gcp-0: 01:44:12 ERROR unit.postgresql-k8s-gcp/0.juju-log Kubernetes service get failed: services "postgresql-k8s-gcp" not found
unit-postgresql-k8s-gcp-0: 01:44:12 ERROR unit.postgresql-k8s-gcp/0.juju-log Kubernetes service patch failed: services "postgresql-k8s-gcp" not found
unit-postgresql-k8s-gcp-0: 01:44:24 ERROR unit.postgresql-k8s-gcp/0.juju-log Failed to get PostgreSQL current timeline id: connection to server at "postgresql-k8s-gcp-primary.test.svc.cluster.local" (10.152.183.151), port 5432 failed: Connection refused
	Is the server running on that host and accepting TCP/IP connections?

unit-postgresql-k8s-gcp-0: 01:44:24 ERROR unit.postgresql-k8s-gcp/0.juju-log Kubernetes service get failed: services "postgresql-k8s-gcp" not found
unit-postgresql-k8s-gcp-0: 01:44:24 ERROR unit.postgresql-k8s-gcp/0.juju-log Kubernetes service patch failed: services "postgresql-k8s-gcp" not found
unit-postgresql-k8s-gcp-0: 01:44:48 ERROR unit.postgresql-k8s-gcp/0.juju-log Kubernetes service get failed: services "postgresql-k8s-gcp" not found
unit-postgresql-k8s-gcp-0: 01:44:48 ERROR unit.postgresql-k8s-gcp/0.juju-log Kubernetes service patch failed: services "postgresql-k8s-gcp" not found
unit-postgresql-k8s-gcp-0: 01:45:03 ERROR unit.postgresql-k8s-gcp/0.juju-log Kubernetes service get failed: services "postgresql-k8s-gcp" not found
unit-postgresql-k8s-gcp-0: 01:45:03 ERROR unit.postgresql-k8s-gcp/0.juju-log Kubernetes service patch failed: services "postgresql-k8s-gcp" not found
unit-postgresql-k8s-gcp-0: 01:45:05 ERROR unit.postgresql-k8s-gcp/0.juju-log Kubernetes service get failed: services "postgresql-k8s-gcp" not found
unit-postgresql-k8s-gcp-0: 01:45:05 ERROR unit.postgresql-k8s-gcp/0.juju-log Kubernetes service patch failed: services "postgresql-k8s-gcp" not found
unit-postgresql-k8s-gcp-0: 01:45:16 ERROR unit.postgresql-k8s-gcp/0.juju-log Kubernetes service get failed: services "postgresql-k8s-gcp" not found
unit-postgresql-k8s-gcp-0: 01:45:16 ERROR unit.postgresql-k8s-gcp/0.juju-log Kubernetes service patch failed: services "postgresql-k8s-gcp" not found
unit-postgresql-k8s-gcp-0: 01:45:39 ERROR unit.postgresql-k8s-gcp/0.juju-log Kubernetes service get failed: services "postgresql-k8s-gcp" not found
unit-postgresql-k8s-gcp-0: 01:45:39 ERROR unit.postgresql-k8s-gcp/0.juju-log Kubernetes service patch failed: services "postgresql-k8s-gcp" not found
unit-postgresql-k8s-gcp-0: 01:45:47 ERROR unit.postgresql-k8s-gcp/0.juju-log Kubernetes service get failed: services "postgresql-k8s-gcp" not found
unit-postgresql-k8s-gcp-0: 01:45:47 ERROR unit.postgresql-k8s-gcp/0.juju-log Kubernetes service patch failed: services "postgresql-k8s-gcp" not found
unit-postgresql-k8s-gcp-0: 01:45:58 ERROR unit.postgresql-k8s-gcp/0.juju-log Kubernetes service get failed: services "postgresql-k8s-gcp" not found
unit-postgresql-k8s-gcp-0: 01:45:58 ERROR unit.postgresql-k8s-gcp/0.juju-log Kubernetes service patch failed: services "postgresql-k8s-gcp" not found
unit-postgresql-k8s-gcp-0: 01:46:07 ERROR unit.postgresql-k8s-gcp/0.juju-log Failed to get PostgreSQL current timeline id: connection to server at "postgresql-k8s-gcp-primary.test.svc.cluster.local" (10.152.183.151), port 5432 failed: Connection refused
	Is the server running on that host and accepting TCP/IP connections?

unit-postgresql-k8s-gcp-0: 01:46:07 ERROR unit.postgresql-k8s-gcp/0.juju-log Kubernetes service get failed: services "postgresql-k8s-gcp" not found
unit-postgresql-k8s-gcp-0: 01:46:08 ERROR unit.postgresql-k8s-gcp/0.juju-log Kubernetes service patch failed: services "postgresql-k8s-gcp" not found
unit-postgresql-k8s-gcp-0: 01:46:32 ERROR unit.postgresql-k8s-gcp/0.juju-log Kubernetes service get failed: services "postgresql-k8s-gcp" not found
unit-postgresql-k8s-gcp-0: 01:46:32 ERROR unit.postgresql-k8s-gcp/0.juju-log Kubernetes service patch failed: services "postgresql-k8s-gcp" not found
unit-postgresql-k8s-gcp-0: 01:46:47 ERROR unit.postgresql-k8s-gcp/0.juju-log Kubernetes service get failed: services "postgresql-k8s-gcp" not found
unit-postgresql-k8s-gcp-0: 01:46:47 ERROR unit.postgresql-k8s-gcp/0.juju-log Kubernetes service patch failed: services "postgresql-k8s-gcp" not found
unit-postgresql-k8s-gcp-0: 01:46:52 ERROR unit.postgresql-k8s-gcp/0.juju-log Kubernetes service get failed: services "postgresql-k8s-gcp" not found
unit-postgresql-k8s-gcp-0: 01:46:52 ERROR unit.postgresql-k8s-gcp/0.juju-log Kubernetes service patch failed: services "postgresql-k8s-gcp" not found
unit-postgresql-k8s-gcp-0: 01:47:01 ERROR unit.postgresql-k8s-gcp/0.juju-log Kubernetes service get failed: services "postgresql-k8s-gcp" not found
unit-postgresql-k8s-gcp-0: 01:47:01 ERROR unit.postgresql-k8s-gcp/0.juju-log Kubernetes service patch failed: services "postgresql-k8s-gcp" not found
unit-new-postgresql-k8s-0: 01:52:03 ERROR unit.new-postgresql-k8s/0.juju-log Restore failed: Cannot restore to the timeline without restore-to-time parameter
unit-new-postgresql-k8s-0: 01:52:08 ERROR unit.new-postgresql-k8s/0.juju-log Restore failed: Cannot restore to the timeline without restore-to-time parameter
unit-new-postgresql-k8s-0: 01:52:14 ERROR unit.new-postgresql-k8s/0.juju-log Restore failed: Cannot restore to the timeline without restore-to-time parameter
unit-new-postgresql-k8s-0: 01:52:20 ERROR unit.new-postgresql-k8s/0.juju-log Restore failed: Cannot restore to the timeline without restore-to-time parameter
unit-new-postgresql-k8s-0: 01:52:31 ERROR unit.new-postgresql-k8s/0.juju-log Restore failed: Cannot restore to the timeline without restore-to-time parameter
unit-new-postgresql-k8s-0: 01:52:51 ERROR unit.new-postgresql-k8s/0.juju-log Restore failed: Cannot restore to the timeline without restore-to-time parameter
unit-new-postgresql-k8s-0: 01:53:24 ERROR unit.new-postgresql-k8s/0.juju-log Restore failed: Cannot restore to the timeline without restore-to-time parameter
unit-new-postgresql-k8s-0: 01:53:57 ERROR unit.new-postgresql-k8s/0.juju-log Restore failed: Cannot restore to the timeline without restore-to-time parameter
unit-new-postgresql-k8s-0: 01:54:30 ERROR unit.new-postgresql-k8s/0.juju-log Restore failed: Cannot restore to the timeline without restore-to-time parameter
unit-new-postgresql-k8s-0: 01:55:03 ERROR unit.new-postgresql-k8s/0.juju-log Restore failed: Cannot restore to the timeline without restore-to-time parameter
unit-new-postgresql-k8s-0: 01:55:19 ERROR unit.new-postgresql-k8s/0.juju-log s3-parameters:13: Failed to create a session 'bucket' in region=region.
Traceback (most recent call last):
  File "/var/lib/juju/agents/unit-new-postgresql-k8s-0/charm/src/backups.py", line 235, in _create_bucket_if_not_exists
    s3 = session.resource(
  File "/var/lib/juju/agents/unit-new-postgresql-k8s-0/charm/venv/boto3/session.py", line 444, in resource
    client = self.client(
  File "/var/lib/juju/agents/unit-new-postgresql-k8s-0/charm/venv/boto3/session.py", line 297, in client
    return self._session.create_client(
  File "/var/lib/juju/agents/unit-new-postgresql-k8s-0/charm/venv/botocore/session.py", line 997, in create_client
    client = client_creator.create_client(
  File "/var/lib/juju/agents/unit-new-postgresql-k8s-0/charm/venv/botocore/client.py", line 165, in create_client
    client_args = self._get_client_args(
  File "/var/lib/juju/agents/unit-new-postgresql-k8s-0/charm/venv/botocore/client.py", line 524, in _get_client_args
    return args_creator.get_client_args(
  File "/var/lib/juju/agents/unit-new-postgresql-k8s-0/charm/venv/botocore/args.py", line 138, in get_client_args
    endpoint = endpoint_creator.create_endpoint(
  File "/var/lib/juju/agents/unit-new-postgresql-k8s-0/charm/venv/botocore/endpoint.py", line 408, in create_endpoint
    raise ValueError(f"Invalid endpoint: {endpoint_url}")
ValueError: Invalid endpoint: endpoint
unit-new-postgresql-k8s-0: 01:55:33 ERROR unit.new-postgresql-k8s/0.juju-log s3-parameters:13: Failed to create a session 'bucket' in region=region.
Traceback (most recent call last):
  File "/var/lib/juju/agents/unit-new-postgresql-k8s-0/charm/src/backups.py", line 235, in _create_bucket_if_not_exists
    s3 = session.resource(
  File "/var/lib/juju/agents/unit-new-postgresql-k8s-0/charm/venv/boto3/session.py", line 444, in resource
    client = self.client(
  File "/var/lib/juju/agents/unit-new-postgresql-k8s-0/charm/venv/boto3/session.py", line 297, in client
    return self._session.create_client(
  File "/var/lib/juju/agents/unit-new-postgresql-k8s-0/charm/venv/botocore/session.py", line 997, in create_client
    client = client_creator.create_client(
  File "/var/lib/juju/agents/unit-new-postgresql-k8s-0/charm/venv/botocore/client.py", line 165, in create_client
    client_args = self._get_client_args(
  File "/var/lib/juju/agents/unit-new-postgresql-k8s-0/charm/venv/botocore/client.py", line 524, in _get_client_args
    return args_creator.get_client_args(
  File "/var/lib/juju/agents/unit-new-postgresql-k8s-0/charm/venv/botocore/args.py", line 138, in get_client_args
    endpoint = endpoint_creator.create_endpoint(
  File "/var/lib/juju/agents/unit-new-postgresql-k8s-0/charm/venv/botocore/endpoint.py", line 408, in create_endpoint
    raise ValueError(f"Invalid endpoint: {endpoint_url}")
ValueError: Invalid endpoint: endpoint
unit-new-postgresql-k8s-0: 01:57:20 ERROR unit.new-postgresql-k8s/0.juju-log Cluster upgrade failed, ensure pre-upgrade checks are ran first.
unit-new-postgresql-k8s-0: 01:57:42 ERROR unit.new-postgresql-k8s/0.juju-log failed to change plugins: 
Traceback (most recent call last):
  File "/var/lib/juju/agents/unit-new-postgresql-k8s-0/charm/lib/charms/postgresql_k8s/v0/postgresql.py", line 338, in enable_disable_extensions
    with self._connect_to_database() as connection, connection.cursor() as cursor:
  File "/var/lib/juju/agents/unit-new-postgresql-k8s-0/charm/lib/charms/tempo_coordinator_k8s/v0/charm_tracing.py", line 1064, in wrapped_function
    return callable(*args, **kwargs)  # type: ignore
  File "/var/lib/juju/agents/unit-new-postgresql-k8s-0/charm/lib/charms/postgresql_k8s/v0/postgresql.py", line 153, in _connect_to_database
    connection = psycopg2.connect(
  File "/var/lib/juju/agents/unit-new-postgresql-k8s-0/charm/venv/psycopg2/__init__.py", line 122, in connect
    conn = _connect(dsn, connection_factory=connection_factory, **kwasync)
psycopg2.OperationalError: connection to server at "new-postgresql-k8s-primary.test.svc.cluster.local" (10.152.183.234), port 5432 failed: Connection refused
	Is the server running on that host and accepting TCP/IP connections?


The above exception was the direct cause of the following exception:

Traceback (most recent call last):
  File "/var/lib/juju/agents/unit-new-postgresql-k8s-0/charm/./src/charm.py", line 723, in _handle_enable_disable_extensions
    self.postgresql.enable_disable_extensions(extensions, database)
  File "/var/lib/juju/agents/unit-new-postgresql-k8s-0/charm/lib/charms/tempo_coordinator_k8s/v0/charm_tracing.py", line 1064, in wrapped_function
    return callable(*args, **kwargs)  # type: ignore
  File "/var/lib/juju/agents/unit-new-postgresql-k8s-0/charm/lib/charms/postgresql_k8s/v0/postgresql.py", line 365, in enable_disable_extensions
    raise PostgreSQLEnableDisableExtensionError() from e
charms.postgresql_k8s.v0.postgresql.PostgreSQLEnableDisableExtensionError

[32mINFO    [0m pytest_operator.plugin:plugin.py:991 Forgetting model main...