[32mINFO    [0m integration.test_backups_gcp:test_backups_gcp.py:280 Getting original backup config
[32mINFO    [0m integration.test_backups_gcp:test_backups_gcp.py:287 Deleting the pod
[32mINFO    [0m httpx:_client.py:1025 HTTP Request: DELETE https://10.1.0.48:16443/api/v1/namespaces/testing/pods/new-postgresql-k8s-0 "HTTP/1.1 200 OK"
[32mINFO    [0m juju.model:__init__.py:3254 Waiting for model:
  new-postgresql-k8s/0 [idle] active: Primary
[32mINFO    [0m juju.model:__init__.py:3254 Waiting for model:
  new-postgresql-k8s/0 [idle] waiting: awaiting for cluster to start
[32mINFO    [0m juju.model:__init__.py:3254 Waiting for model:
  new-postgresql-k8s/0 [idle] waiting: awaiting for cluster to start
[32mINFO    [0m juju.model:__init__.py:3254 Waiting for model:
  new-postgresql-k8s/0 [idle] active: Primary
[32mINFO    [0m integration.test_backups_gcp:test_backups_gcp.py:79 deleting the previously created backups
[32mINFO    [0m pytest_operator.plugin:plugin.py:929 Model status:

Model    Controller          Cloud/Region        Version  SLA          Timestamp
testing  concierge-microk8s  microk8s/localhost  3.6.2    unsupported  02:15:45Z

App                 Version  Status  Scale  Charm           Channel        Rev  Address         Exposed  Message
new-postgresql-k8s  14.15    active      1  postgresql-k8s                   2  10.152.183.117  no       
s3-integrator                active      1  s3-integrator   latest/stable   77  10.152.183.148  no       

Unit                   Workload  Agent  Address      Ports  Message
new-postgresql-k8s/0*  active    idle   10.1.115.18         Primary
s3-integrator/0*       active    idle   10.1.115.8          

[32mINFO    [0m pytest_operator.plugin:plugin.py:935 Juju error logs:

unit-postgresql-k8s-gcp-0: 01:47:33 ERROR unit.postgresql-k8s-gcp/0.juju-log pgdata folder not found in /var/lib/postgresql/data/pgdata
unit-postgresql-k8s-gcp-0: 02:03:09 ERROR unit.postgresql-k8s-gcp/0.juju-log Failed to get PostgreSQL current timeline id: connection to server at "postgresql-k8s-gcp-primary.testing.svc.cluster.local" (10.152.183.131), port 5432 failed: Connection refused
	Is the server running on that host and accepting TCP/IP connections?

unit-postgresql-k8s-gcp-0: 02:05:59 ERROR unit.postgresql-k8s-gcp/0.juju-log failed to change plugins: 
Traceback (most recent call last):
  File "/var/lib/juju/agents/unit-postgresql-k8s-gcp-0/charm/lib/charms/postgresql_k8s/v0/postgresql.py", line 338, in enable_disable_extensions
    with self._connect_to_database() as connection, connection.cursor() as cursor:
  File "/var/lib/juju/agents/unit-postgresql-k8s-gcp-0/charm/lib/charms/tempo_coordinator_k8s/v0/charm_tracing.py", line 1065, in wrapped_function
    return callable(*args, **kwargs)  # type: ignore
  File "/var/lib/juju/agents/unit-postgresql-k8s-gcp-0/charm/lib/charms/postgresql_k8s/v0/postgresql.py", line 153, in _connect_to_database
    connection = psycopg2.connect(
  File "/var/lib/juju/agents/unit-postgresql-k8s-gcp-0/charm/venv/lib/python3.10/site-packages/psycopg2/__init__.py", line 122, in connect
    conn = _connect(dsn, connection_factory=connection_factory, **kwasync)
psycopg2.OperationalError: connection to server at "postgresql-k8s-gcp-primary.testing.svc.cluster.local" (10.152.183.211), port 5432 failed: Connection refused
	Is the server running on that host and accepting TCP/IP connections?


The above exception was the direct cause of the following exception:

Traceback (most recent call last):
  File "/var/lib/juju/agents/unit-postgresql-k8s-gcp-0/charm/src/charm.py", line 764, in _handle_enable_disable_extensions
    self.postgresql.enable_disable_extensions(extensions, database)
  File "/var/lib/juju/agents/unit-postgresql-k8s-gcp-0/charm/lib/charms/tempo_coordinator_k8s/v0/charm_tracing.py", line 1065, in wrapped_function
    return callable(*args, **kwargs)  # type: ignore
  File "/var/lib/juju/agents/unit-postgresql-k8s-gcp-0/charm/lib/charms/postgresql_k8s/v0/postgresql.py", line 365, in enable_disable_extensions
    raise PostgreSQLEnableDisableExtensionError() from e
charms.postgresql_k8s.v0.postgresql.PostgreSQLEnableDisableExtensionError
unit-postgresql-k8s-gcp-0: 02:06:12 ERROR unit.postgresql-k8s-gcp/0.juju-log failed to change plugins: 
Traceback (most recent call last):
  File "/var/lib/juju/agents/unit-postgresql-k8s-gcp-0/charm/lib/charms/postgresql_k8s/v0/postgresql.py", line 338, in enable_disable_extensions
    with self._connect_to_database() as connection, connection.cursor() as cursor:
  File "/var/lib/juju/agents/unit-postgresql-k8s-gcp-0/charm/lib/charms/tempo_coordinator_k8s/v0/charm_tracing.py", line 1065, in wrapped_function
    return callable(*args, **kwargs)  # type: ignore
  File "/var/lib/juju/agents/unit-postgresql-k8s-gcp-0/charm/lib/charms/postgresql_k8s/v0/postgresql.py", line 153, in _connect_to_database
    connection = psycopg2.connect(
  File "/var/lib/juju/agents/unit-postgresql-k8s-gcp-0/charm/venv/lib/python3.10/site-packages/psycopg2/__init__.py", line 122, in connect
    conn = _connect(dsn, connection_factory=connection_factory, **kwasync)
psycopg2.OperationalError: connection to server at "postgresql-k8s-gcp-primary.testing.svc.cluster.local" (10.152.183.211), port 5432 failed: Connection refused
	Is the server running on that host and accepting TCP/IP connections?


The above exception was the direct cause of the following exception:

Traceback (most recent call last):
  File "/var/lib/juju/agents/unit-postgresql-k8s-gcp-0/charm/src/charm.py", line 764, in _handle_enable_disable_extensions
    self.postgresql.enable_disable_extensions(extensions, database)
  File "/var/lib/juju/agents/unit-postgresql-k8s-gcp-0/charm/lib/charms/tempo_coordinator_k8s/v0/charm_tracing.py", line 1065, in wrapped_function
    return callable(*args, **kwargs)  # type: ignore
  File "/var/lib/juju/agents/unit-postgresql-k8s-gcp-0/charm/lib/charms/postgresql_k8s/v0/postgresql.py", line 365, in enable_disable_extensions
    raise PostgreSQLEnableDisableExtensionError() from e
charms.postgresql_k8s.v0.postgresql.PostgreSQLEnableDisableExtensionError
unit-new-postgresql-k8s-0: 02:06:18 ERROR unit.new-postgresql-k8s/0.juju-log failed to change plugins: 
Traceback (most recent call last):
  File "/var/lib/juju/agents/unit-new-postgresql-k8s-0/charm/lib/charms/postgresql_k8s/v0/postgresql.py", line 338, in enable_disable_extensions
    with self._connect_to_database() as connection, connection.cursor() as cursor:
  File "/var/lib/juju/agents/unit-new-postgresql-k8s-0/charm/lib/charms/tempo_coordinator_k8s/v0/charm_tracing.py", line 1065, in wrapped_function
    return callable(*args, **kwargs)  # type: ignore
  File "/var/lib/juju/agents/unit-new-postgresql-k8s-0/charm/lib/charms/postgresql_k8s/v0/postgresql.py", line 153, in _connect_to_database
    connection = psycopg2.connect(
  File "/var/lib/juju/agents/unit-new-postgresql-k8s-0/charm/venv/lib/python3.10/site-packages/psycopg2/__init__.py", line 122, in connect
    conn = _connect(dsn, connection_factory=connection_factory, **kwasync)
psycopg2.OperationalError: connection to server at "new-postgresql-k8s-primary.testing.svc.cluster.local" (10.152.183.47), port 5432 failed: Connection refused
	Is the server running on that host and accepting TCP/IP connections?


The above exception was the direct cause of the following exception:

Traceback (most recent call last):
  File "/var/lib/juju/agents/unit-new-postgresql-k8s-0/charm/src/charm.py", line 764, in _handle_enable_disable_extensions
    self.postgresql.enable_disable_extensions(extensions, database)
  File "/var/lib/juju/agents/unit-new-postgresql-k8s-0/charm/lib/charms/tempo_coordinator_k8s/v0/charm_tracing.py", line 1065, in wrapped_function
    return callable(*args, **kwargs)  # type: ignore
  File "/var/lib/juju/agents/unit-new-postgresql-k8s-0/charm/lib/charms/postgresql_k8s/v0/postgresql.py", line 365, in enable_disable_extensions
    raise PostgreSQLEnableDisableExtensionError() from e
charms.postgresql_k8s.v0.postgresql.PostgreSQLEnableDisableExtensionError
unit-new-postgresql-k8s-0: 02:06:32 ERROR unit.new-postgresql-k8s/0.juju-log failed to change plugins: 
Traceback (most recent call last):
  File "/var/lib/juju/agents/unit-new-postgresql-k8s-0/charm/lib/charms/postgresql_k8s/v0/postgresql.py", line 338, in enable_disable_extensions
    with self._connect_to_database() as connection, connection.cursor() as cursor:
  File "/var/lib/juju/agents/unit-new-postgresql-k8s-0/charm/lib/charms/tempo_coordinator_k8s/v0/charm_tracing.py", line 1065, in wrapped_function
    return callable(*args, **kwargs)  # type: ignore
  File "/var/lib/juju/agents/unit-new-postgresql-k8s-0/charm/lib/charms/postgresql_k8s/v0/postgresql.py", line 153, in _connect_to_database
    connection = psycopg2.connect(
  File "/var/lib/juju/agents/unit-new-postgresql-k8s-0/charm/venv/lib/python3.10/site-packages/psycopg2/__init__.py", line 122, in connect
    conn = _connect(dsn, connection_factory=connection_factory, **kwasync)
psycopg2.OperationalError: connection to server at "new-postgresql-k8s-primary.testing.svc.cluster.local" (10.152.183.47), port 5432 failed: Connection refused
	Is the server running on that host and accepting TCP/IP connections?


The above exception was the direct cause of the following exception:

Traceback (most recent call last):
  File "/var/lib/juju/agents/unit-new-postgresql-k8s-0/charm/src/charm.py", line 764, in _handle_enable_disable_extensions
    self.postgresql.enable_disable_extensions(extensions, database)
  File "/var/lib/juju/agents/unit-new-postgresql-k8s-0/charm/lib/charms/tempo_coordinator_k8s/v0/charm_tracing.py", line 1065, in wrapped_function
    return callable(*args, **kwargs)  # type: ignore
  File "/var/lib/juju/agents/unit-new-postgresql-k8s-0/charm/lib/charms/postgresql_k8s/v0/postgresql.py", line 365, in enable_disable_extensions
    raise PostgreSQLEnableDisableExtensionError() from e
charms.postgresql_k8s.v0.postgresql.PostgreSQLEnableDisableExtensionError
unit-new-postgresql-k8s-0: 02:08:13 ERROR unit.new-postgresql-k8s/0.juju-log Restore failed: Cannot restore to the timeline without restore-to-time parameter
unit-new-postgresql-k8s-0: 02:08:22 ERROR unit.new-postgresql-k8s/0.juju-log Restore failed: Cannot restore to the timeline without restore-to-time parameter
unit-new-postgresql-k8s-0: 02:08:31 ERROR unit.new-postgresql-k8s/0.juju-log Restore failed: Cannot restore to the timeline without restore-to-time parameter
unit-new-postgresql-k8s-0: 02:08:43 ERROR unit.new-postgresql-k8s/0.juju-log Restore failed: Cannot restore to the timeline without restore-to-time parameter
unit-new-postgresql-k8s-0: 02:08:59 ERROR unit.new-postgresql-k8s/0.juju-log Restore failed: Cannot restore to the timeline without restore-to-time parameter
unit-new-postgresql-k8s-0: 02:09:23 ERROR unit.new-postgresql-k8s/0.juju-log Restore failed: Cannot restore to the timeline without restore-to-time parameter
unit-new-postgresql-k8s-0: 02:10:02 ERROR unit.new-postgresql-k8s/0.juju-log Restore failed: Cannot restore to the timeline without restore-to-time parameter
unit-new-postgresql-k8s-0: 02:10:40 ERROR unit.new-postgresql-k8s/0.juju-log Restore failed: Cannot restore to the timeline without restore-to-time parameter
unit-new-postgresql-k8s-0: 02:11:19 ERROR unit.new-postgresql-k8s/0.juju-log Restore failed: Cannot restore to the timeline without restore-to-time parameter
unit-new-postgresql-k8s-0: 02:11:57 ERROR unit.new-postgresql-k8s/0.juju-log Restore failed: Cannot restore to the timeline without restore-to-time parameter
unit-new-postgresql-k8s-0: 02:12:13 ERROR unit.new-postgresql-k8s/0.juju-log s3-parameters:13: Failed to create a session 'bucket' in region=region.
Traceback (most recent call last):
  File "/var/lib/juju/agents/unit-new-postgresql-k8s-0/charm/src/backups.py", line 234, in _create_bucket_if_not_exists
    s3 = session.resource(
  File "/var/lib/juju/agents/unit-new-postgresql-k8s-0/charm/venv/lib/python3.10/site-packages/boto3/session.py", line 444, in resource
    client = self.client(
  File "/var/lib/juju/agents/unit-new-postgresql-k8s-0/charm/venv/lib/python3.10/site-packages/boto3/session.py", line 297, in client
    return self._session.create_client(
  File "/var/lib/juju/agents/unit-new-postgresql-k8s-0/charm/venv/lib/python3.10/site-packages/botocore/session.py", line 997, in create_client
    client = client_creator.create_client(
  File "/var/lib/juju/agents/unit-new-postgresql-k8s-0/charm/venv/lib/python3.10/site-packages/botocore/client.py", line 165, in create_client
    client_args = self._get_client_args(
  File "/var/lib/juju/agents/unit-new-postgresql-k8s-0/charm/venv/lib/python3.10/site-packages/botocore/client.py", line 524, in _get_client_args
    return args_creator.get_client_args(
  File "/var/lib/juju/agents/unit-new-postgresql-k8s-0/charm/venv/lib/python3.10/site-packages/botocore/args.py", line 138, in get_client_args
    endpoint = endpoint_creator.create_endpoint(
  File "/var/lib/juju/agents/unit-new-postgresql-k8s-0/charm/venv/lib/python3.10/site-packages/botocore/endpoint.py", line 408, in create_endpoint
    raise ValueError(f"Invalid endpoint: {endpoint_url}")
ValueError: Invalid endpoint: endpoint
unit-new-postgresql-k8s-0: 02:12:29 ERROR unit.new-postgresql-k8s/0.juju-log s3-parameters:13: Failed to create a session 'bucket' in region=region.
Traceback (most recent call last):
  File "/var/lib/juju/agents/unit-new-postgresql-k8s-0/charm/src/backups.py", line 234, in _create_bucket_if_not_exists
    s3 = session.resource(
  File "/var/lib/juju/agents/unit-new-postgresql-k8s-0/charm/venv/lib/python3.10/site-packages/boto3/session.py", line 444, in resource
    client = self.client(
  File "/var/lib/juju/agents/unit-new-postgresql-k8s-0/charm/venv/lib/python3.10/site-packages/boto3/session.py", line 297, in client
    return self._session.create_client(
  File "/var/lib/juju/agents/unit-new-postgresql-k8s-0/charm/venv/lib/python3.10/site-packages/botocore/session.py", line 997, in create_client
    client = client_creator.create_client(
  File "/var/lib/juju/agents/unit-new-postgresql-k8s-0/charm/venv/lib/python3.10/site-packages/botocore/client.py", line 165, in create_client
    client_args = self._get_client_args(
  File "/var/lib/juju/agents/unit-new-postgresql-k8s-0/charm/venv/lib/python3.10/site-packages/botocore/client.py", line 524, in _get_client_args
    return args_creator.get_client_args(
  File "/var/lib/juju/agents/unit-new-postgresql-k8s-0/charm/venv/lib/python3.10/site-packages/botocore/args.py", line 138, in get_client_args
    endpoint = endpoint_creator.create_endpoint(
  File "/var/lib/juju/agents/unit-new-postgresql-k8s-0/charm/venv/lib/python3.10/site-packages/botocore/endpoint.py", line 408, in create_endpoint
    raise ValueError(f"Invalid endpoint: {endpoint_url}")
ValueError: Invalid endpoint: endpoint
unit-new-postgresql-k8s-0: 02:14:22 ERROR unit.new-postgresql-k8s/0.juju-log Cluster upgrade failed, ensure pre-upgrade checks are ran first.

[32mINFO    [0m pytest_operator.plugin:plugin.py:1017 Forgetting model main...