[32mINFO    [0m pytest_operator.plugin:plugin.py:951 Model status:

Model    Controller          Cloud/Region        Version  SLA          Timestamp
testing  concierge-microk8s  microk8s/localhost  3.6.9    unsupported  01:48:02Z

App                  Version  Status  Scale  Charm                Channel      Rev  Address         Exposed  Message
postgresql-k8s       14.19    active      3  postgresql-k8s                      0  10.152.183.234  no       
postgresql-test-app           active      1  postgresql-test-app  latest/edge  410  10.152.183.72   no       received database credentials of the first database

Unit                    Workload  Agent  Address       Ports  Message
postgresql-k8s/0        active    idle   10.1.113.139         Primary (degraded)
postgresql-k8s/1        active    idle   10.1.113.141         Primary
postgresql-k8s/2*       active    idle   10.1.113.140         
postgresql-test-app/0*  active    idle   10.1.113.142         received database credentials of the first database

[32mINFO    [0m pytest_operator.plugin:plugin.py:957 Juju error logs:

unit-postgresql-k8s-1: 01:35:16 ERROR unit.postgresql-k8s/1.juju-log Failed to restart patroni
Traceback (most recent call last):
  File "/var/lib/juju/agents/unit-postgresql-k8s-1/charm/src/charm.py", line 1523, in _on_update_status
    container.restart(self.postgresql_service)
  File "/var/lib/juju/agents/unit-postgresql-k8s-1/charm/venv/lib/python3.10/site-packages/ops/model.py", line 2661, in restart
    self._pebble.restart_services(service_names)
  File "/var/lib/juju/agents/unit-postgresql-k8s-1/charm/venv/lib/python3.10/site-packages/ops/pebble.py", line 2405, in restart_services
    return self._services_action('restart', services, timeout, delay)
  File "/var/lib/juju/agents/unit-postgresql-k8s-1/charm/venv/lib/python3.10/site-packages/ops/pebble.py", line 2432, in _services_action
    raise ChangeError(change.err, change)
ops.pebble.ChangeError: cannot perform the following tasks:
- Start service "postgresql" (cannot start service while terminating)
----- Logs from task 0 -----
2025-10-04T01:35:16Z INFO Service "postgresql" already stopping.
----- Logs from task 1 -----
2025-10-04T01:35:16Z ERROR cannot start service while terminating
-----

[32mINFO    [0m pytest_operator.plugin:plugin.py:1039 Forgetting model main...